<mujoco model="reacher">
	<compiler angle="radian" inertiafromgeom="true" coordinate="local"/>
	<default>
		<joint armature="1" damping="1" limited="true"/>
		<geom contype="0" friction="1 0.1 0.1" rgba="0.7 0.7 0.7 1"/>
		<default class="dyn_motor">
			<geom rgba="0.1 0.1 0.1 .3" size=".019 .0143 .0233"
				  type="box" conaffinity="0" mass="0.136"/>
			<velocity ctrllimited="true" ctrlrange="-2.0 2.0"
					  forcelimited="true" forcerange="-2.0 2.0"
					  kv="2"/>
		</default>
	</default>
	<option gravity="0 0 -9.81" integrator="RK4" timestep="0.01"/>
	<worldbody>
		<light diffuse=".5 .5 .4" pos="0 0 3" dir="0 0 -1"/>
		<body>
			<geom type="plane" size="1 1 0.01" rgba=".8 .8 .8 1"/>
		</body>
		<!-- Arm -->
		<geom name="motor0_geom" class="dyn_motor" pos="0 0 .0233"/>
		<body name="angle_body" pos="0 0 0.0349">
			<geom name="angle_geom" pos="0 0 0.0349" mass="0.01" rgba="1 0 0 .3" size=".01" type="sphere"/>
			<joint axis="1 0 0" range="-1 1.8" name="joint0" type="hinge"/>
			<body name="motor2_body" pos="0 0.0247 0.0595" euler="-0.785 0 0">
				<joint axis="1 0 0" name="joint1" range="-2.0 2.0" type="hinge"/>
				<geom name="motor1_geom" class="dyn_motor" pos="0 0 0.0116"/>
				<body name="tip" pos="0 0 .0349">
					<geom type="sphere" size=".005" rgba="1 1 1 1" mass="0"/>
				</body>
			</body>
		</body>
		<body name="target" pos="0 0 0">
			<joint armature="0" axis="0 1 0" damping="0.1" limited="true" name="target_y" range="-.2 .2" stiffness="0" type="slide"/>
			<joint armature="0" axis="0 0 1" damping="0.1" limited="true" name="target_z" range="-.2 .2" stiffness="0" type="slide"/>
			<geom conaffinity="0" contype="0" name="target" pos="0 0 0" rgba="0.2 0.9 0.2 1" size=".005" type="sphere"/>
		</body>
	</worldbody>
	<actuator>
		<velocity joint="joint0" class="dyn_motor"/>
		<velocity joint="joint1" class="dyn_motor"/>
		<position joint="target_y" kp="2" />
		<position joint="target_z" kp="2" />
	</actuator>
</mujoco>
